File: examples/reader_netzsch/ExpDat_VKI_P50_20K_50ml+20ml_01.txt
#EXPORTTYPE:DATA ALL
#FILE:VKI_P50_20K_50ml+20ml_01.ngb-ds3
#FORMAT:NETZSCH5
#FTYPE:ANSI
#IDENTITY:Sample
#DECIMAL:POINT
#SEPARATOR:SEMICOLON
#MTYPE:DSC
#INSTRUMENT:NETZSCH STA 449F3
#PROJECT:ReChar
#DATE/TIME:17.05.2023 12:02
#CORR. FILE:Baseline_20K_TGA_01.ngb-bs3
#TEMPCAL:calib_20Kmin_TGA_20ml+50ml_2022.ngb-ts3
#SENSITIVITY:calib_20Kmin_cp_20ml+50ml_2022.ngb-es3
#LABORATORY:VKI
#OPERATOR:Gertjan
#REMARK:20K/min TGA determination withOUT lid  May 2023.   P50 campaign
#SAMPLE:P50
#SAMPLE MASS /mg:32.966
#MATERIAL:blank
#REFERENCE:empty
#REFERENCE MASS /mg:0
#TYPE OF CRUCIBLE:DSC/TG pan Pt-Rh+Al2O3
#SAMPLE CRUCIBLE MASS /mg:0.0
#REFERENCE CRUCIBLE MASS /mg:297.556
#DSC RANGE /�V:5000
#TG RANGE /mg:35000
#TAU-R:---
#CORR. CODE:020
#EXO:-1
#RANGE:27�C....1100�C/0.0....20.0K/min
#SEGMENT:S1-3/3
#SEG. 1:27�C/00:20/27�C
#SEG. 2:27�C/20.0(K/min)/1100�C
#SEG. 3:1100�C/00:20/1100�C

##Temp./�C;Time/min;DSC/(mW/mg);Mass/%;Gas Flow(protective)/(ml/min);Sensit./(uV/mW);Segment
  26.34600; 0.00000; 2.929347e-003;100.00000;20.00000;1.15347;1
  26.34100; 0.04000; 2.949414e-003;100.00000;20.00000;1.15347;1
  26.35300; 0.08000; 2.788895e-003;100.00000;20.00000;1.15347;1
  26.35100; 0.12000; 2.869152e-003;100.00000;20.00000;1.15347;1
  26.36500; 0.16000; 2.568185e-003;100.00000;20.00000;1.15348;1
  26.37000; 0.20000; 2.427736e-003;100.00000;20.00000;1.15348;1
  26.37900; 0.24000; 2.447795e-003;100.00607;20.00000;1.15348;1
  26.37500; 0.28000; 2.327414e-003;100.00607;20.00000;1.15348;1
  26.39000; 0.32000; 2.207024e-003;100.00607;20.00000;1.15348;1
  26.38900; 0.36000; 2.207024e-003;100.00607;20.00000;1.15348;1
  26.38400; 0.40000; 2.227091e-003;100.00607;20.00000;1.15348;1
  26.38500; 0.44000; 2.186962e-003;100.00607;20.00000;1.15348;1
  26.37700; 0.48000; 2.026455e-003;100.00607;20.00000;1.15348;1
  26.40600; 0.52000; 2.166890e-003;100.00607;20.00000;1.15349;1
  26.40000; 0.56000; 2.126765e-003;100.00607;20.00000;1.15348;1
  26.39800; 0.60000; 1.906064e-003;100.00607;20.00000;1.15348;1
  26.42800; 0.64000; 2.066562e-003;100.01213;20.00000;1.15349;1
  26.40100; 0.68000; 2.006382e-003;100.01213;20.00000;1.15348;1
  26.42100; 0.72000; 2.106692e-003;100.01213;20.00000;1.15349;1
  26.45500; 0.76000; 2.066551e-003;100.01213;20.00000;1.15350;1
  26.46200; 0.80000; 1.966230e-003;100.01820;20.00000;1.15350;1
  26.44500; 0.84000; 2.146809e-003;100.01820;20.00000;1.15349;1
  26.47500; 0.88000; 2.046479e-003;100.02427;20.00000;1.15350;1
  26.47900; 0.92000; 2.247111e-003;100.02730;20.00000;1.15350;1
  26.48900; 0.96000; 2.287234e-003;100.03337;20.00000;1.15350;1
  26.49500; 1.00000; 2.447738e-003;100.03640;20.00000;1.15351;1
  26.50300; 1.04000; 2.507924e-003;100.03943;20.00000;1.15351;1
  26.50900; 1.08000; 2.608238e-003;100.04550;20.00000;1.15351;1
  26.52700; 1.12000; 2.808861e-003;100.05157;20.00000;1.15351;1
  26.55800; 1.16000; 3.009475e-003;100.05157;20.00000;1.15352;1
  26.57500; 1.20000; 3.129843e-003;100.06067;20.00000;1.15352;1
  26.59100; 1.24000; 3.129833e-003;100.06370;20.00000;1.15353;1
  26.58100; 1.28000; 3.370595e-003;100.06674;20.00000;1.15353;1
  26.61900; 1.32000; 3.571198e-003;100.06977;20.00000;1.15353;1
  26.62700; 1.36000; 3.892198e-003;100.06977;20.00000;1.15354;1
  26.64700; 1.40000; 4.072748e-003;100.07584;20.00000;1.15354;1
  26.67300; 1.44000; 4.253290e-003;100.07584;20.00000;1.15355;1
  26.70500; 1.48000; 4.393701e-003;100.08190;20.00000;1.15355;1
  26.72000; 1.52000; 4.634437e-003;100.08797;20.00000;1.15356;1
  26.74300; 1.56000; 5.035664e-003;100.09100;20.00000;1.15356;1
  26.77600; 1.60000; 5.316502e-003;100.08797;20.00000;1.15357;1
  26.77500; 1.64000; 5.456939e-003;100.09100;20.00000;1.15357;1
  26.79600; 1.68000; 5.677599e-003;100.09404;20.00000;1.15358;1
  26.82600; 1.72000; 5.878186e-003;100.09707;20.00000;1.15358;1
  26.86500; 1.76000; 6.098821e-003;100.09404;20.00000;1.15359;1
  26.88000; 1.80000; 6.279359e-003;100.09707;20.00000;1.15359;1
  26.91000; 1.84000; 6.720679e-003;100.10314;20.00000;1.15360;1
  26.93500; 1.88000; 6.921262e-003;100.10314;20.00000;1.15361;1
  26.97700; 1.92000; 7.141880e-003;100.10920;20.00000;1.15362;1
  26.99500; 1.96000; 7.242161e-003;100.10314;20.00000;1.15362;1
  27.03200; 2.00000; 7.543026e-003;100.10314;20.00000;1.15363;1
  27.06100; 2.04000; 7.924143e-003;100.10920;20.00000;1.15364;1
  27.09100; 2.08000; 8.124706e-003;100.10920;20.00000;1.15364;1
  27.13600; 2.12000; 8.345303e-003;100.10920;20.00000;1.15365;1
  27.16400; 2.16000; 8.325195e-003;100.10920;20.00000;1.15366;1
  27.18600; 2.20000; 8.485643e-003;100.10920;20.00000;1.15367;1
  27.22900; 2.24000; 8.706236e-003;100.11527;20.00000;1.15367;1
  27.26400; 2.28000; 8.906778e-003;100.11830;20.00000;1.15368;1
  27.29100; 2.32000; 9.147453e-003;100.12134;20.00000;1.15369;1
  27.33200; 2.36000; 9.488399e-003;100.12134;20.00000;1.15370;1
  27.35500; 2.40000; 9.508416e-003;100.11830;20.00000;1.15370;1
  27.37900; 2.44000; 9.468251e-003;100.11830;20.00000;1.15371;1
  27.41300; 2.48000; 9.849322e-003;100.11830;20.00000;1.15372;1
  27.43500; 2.52000; 9.949576e-003;100.11830;20.00000;1.15372;1
  27.48400; 2.56000; 1.019019e-002;100.12134;20.00000;1.15373;1
  27.51100; 2.60000; 1.006978e-002;100.12134;20.00000;1.15374;1
  27.53900; 2.64000; 1.027032e-002;100.12437;20.00000;1.15375;1
  27.58900; 2.68000; 1.035045e-002;100.12134;20.00000;1.15376;1
  27.62300; 2.72000; 1.039050e-002;100.12437;20.00000;1.15376;1
  27.64400; 2.76000; 1.049075e-002;100.12437;20.00000;1.15377;1
  27.68600; 2.80000; 1.059096e-002;100.12740;20.00000;1.15378;1
  27.72300; 2.84000; 1.073129e-002;100.12740;20.00000;1.15379;1
  27.75300; 2.88000; 1.079140e-002;100.12740;20.00000;1.15379;1
  27.78800; 2.92000; 1.095179e-002;100.13044;20.00000;1.15380;1
  27.81700; 2.96000; 1.087150e-002;100.12740;20.00000;1.15381;1
  27.83400; 3.00000; 1.105198e-002;100.12740;20.00000;1.15381;1
  27.88700; 3.04000; 1.101175e-002;100.12740;20.00000;1.15382;1
  27.92100; 3.08000; 1.117214e-002;100.12437;20.00000;1.15383;1
  27.95700; 3.12000; 1.119212e-002;100.12437;20.00000;1.15384;1
  28.01100; 3.16000; 1.129229e-002;100.12437;20.00000;1.15385;1
  28.02000; 3.20000; 1.113181e-002;100.12437;20.00000;1.15386;1
  28.06400; 3.24000; 1.107154e-002;100.13044;20.00000;1.15387;1
  28.08000; 3.28000; 1.123196e-002;100.12740;20.00000;1.15387;1
  28.10400; 3.32000; 1.097117e-002;100.12740;20.00000;1.15387;1
  28.14100; 3.36000; 1.101120e-002;100.12740;20.00000;1.15388;1
  28.18300; 3.40000; 1.109134e-002;100.12740;20.00000;1.15389;1
  28.21200; 3.44000; 1.113139e-002;100.12740;20.00000;1.15390;1
  28.25300; 3.48000; 1.113130e-002;100.13347;20.00000;1.15391;1
  28.28100; 3.52000; 1.089057e-002;100.13347;20.00000;1.15391;1
  28.31400; 3.56000; 1.097072e-002;100.13347;20.00000;1.15392;1
  28.32900; 3.60000; 1.073001e-002;100.13347;20.00000;1.15392;1
  28.38100; 3.64000; 1.070985e-002;100.13347;20.00000;1.15394;1
  28.39700; 3.68000; 1.064965e-002;100.13347;20.00000;1.15394;1
  28.42500; 3.72000; 1.074987e-002;100.13347;20.00000;1.15395;1
  28.45500; 3.76000; 1.056930e-002;100.13347;20.00000;1.15395;1
  28.47800; 3.80000; 1.046898e-002;100.13347;20.00000;1.15396;1
  28.52000; 3.84000; 1.044884e-002;100.13347;20.00000;1.15397;1
  28.55200; 3.88000; 1.020811e-002;100.13347;20.00000;1.15398;1
  28.59300; 3.92000; 1.030831e-002;100.13347;20.00000;1.15398;1
  28.60800; 3.96000; 1.024811e-002;100.13347;20.00000;1.15399;1
  28.61700; 4.00000; 9.987378e-003;100.13347;20.00000;1.15399;1
  28.67800; 4.04000; 1.004742e-002;100.13347;20.00000;1.15400;1
  28.69500; 4.08000; 9.907007e-003;100.13347;20.00000;1.15401;1
  28.70400; 4.12000; 9.666335e-003;100.13347;20.00000;1.15401;1
  28.73900; 4.16000; 9.746487e-003;100.13347;20.00000;1.15402;1
  28.76500; 4.20000; 9.786546e-003;100.13347;20.00000;1.15402;1
  28.79700; 4.24000; 9.465617e-003;100.13347;20.00000;1.15403;1
  28.81800; 4.28000; 9.385361e-003;100.13347;20.00000;1.15403;1
  28.85600; 4.32000; 9.345184e-003;100.13347;20.00000;1.15404;1
  28.89000; 4.36000; 9.345122e-003;100.13347;20.00000;1.15405;1
  28.91000; 4.40000; 9.284926e-003;100.13347;20.00000;1.15406;1
  28.92000; 4.44000; 9.024208e-003;100.13347;20.00000;1.15406;1
  28.94900; 4.48000; 9.144478e-003;100.13347;20.00000;1.15406;1
  28.96600; 4.52000; 8.943913e-003;100.13347;20.00000;1.15407;1
  28.99400; 4.56000; 8.803490e-003;100.13347;20.00000;1.15407;1
  29.02500; 4.60000; 8.783384e-003;100.13347;20.00000;1.15408;1
  29.03300; 4.64000; 8.683104e-003;100.13347;20.00000;1.15408;1
  29.05800; 4.68000; 8.462476e-003;100.13347;20.00000;1.15409;1
  29.07000; 4.72000; 8.161658e-003;100.13347;20.00000;1.15409;1
  29.11800; 4.76000; 8.181636e-003;100.13347;20.00000;1.15410;1
  29.13200; 4.80000; 7.961030e-003;100.13347;20.00000;1.15411;1
  29.14300; 4.84000; 7.860749e-003;100.13347;20.00000;1.15411;1
  29.18000; 4.88000; 7.740377e-003;100.13044;20.00000;1.15412;1
  29.20400; 4.92000; 7.700235e-003;100.13044;20.00000;1.15412;1
  29.22500; 4.96000; 7.539784e-003;100.12740;20.00000;1.15413;1
  29.22900; 5.00000; 7.359304e-003;100.12740;20.00000;1.15413;1
  29.25700; 5.04000; 7.279055e-003;100.12740;20.00000;1.15413;1
  29.28300; 5.08000; 7.238913e-003;100.12740;20.00000;1.15414;1
  29.29700; 5.12000; 7.198789e-003;100.12740;20.00000;1.15414;1
  29.31800; 5.16000; 7.078446e-003;100.12740;20.00000;1.15415;1
  29.33800; 5.20000; 6.877898e-003;100.12740;20.00000;1.15415;1
  29.36100; 5.24000; 6.817711e-003;100.12740;20.00000;1.15416;1
  29.36800; 5.28000; 6.777598e-003;100.13347;20.00000;1.15416;1
  29.38300; 5.32000; 6.536954e-003;100.13347;20.00000;1.15416;1
  29.39800; 5.36000; 6.436676e-003;100.13347;20.00000;1.15416;1
  29.41500; 5.40000; 6.316343e-003;100.13347;20.00000;1.15417;1
  29.44600; 5.44000; 6.296254e-003;100.13347;20.00000;1.15418;1
  29.45500; 5.48000; 6.115777e-003;100.13347;20.00000;1.15418;1
  29.47700; 5.52000; 5.915235e-003;100.13347;20.00000;1.15418;1
  29.51200; 5.56000; 5.895144e-003;100.13347;20.00000;1.15419;1
  29.52600; 5.60000; 5.814922e-003;100.13954;20.00000;1.15419;1
  29.53800; 5.64000; 5.814909e-003;100.13954;20.00000;1.15420;1
  29.53600; 5.68000; 5.474032e-003;100.13954;20.00000;1.15419;1
  29.57600; 5.72000; 5.514092e-003;100.13954;20.00000;1.15420;1
  29.58800; 5.76000; 5.514079e-003;100.13954;20.00000;1.15421;1
  29.60000; 5.80000; 5.273453e-003;100.13650;20.00000;1.15421;1
  29.60700; 5.84000; 5.213292e-003;100.13650;20.00000;1.15421;1
  29.63200; 5.88000; 5.133063e-003;100.13650;20.00000;1.15422;1
  29.63700; 5.92000; 5.092956e-003;100.13347;20.00000;1.15422;1
  29.64500; 5.96000; 4.792184e-003;100.13347;20.00000;1.15422;1
  29.65700; 6.00000; 4.812224e-003;100.13347;20.00000;1.15422;1
  29.66400; 6.04000; 4.711963e-003;100.13044;20.00000;1.15422;1
  29.66800; 6.08000; 4.812213e-003;100.13044;20.00000;1.15422;1
  29.69000; 6.12000; 4.671837e-003;100.13044;20.00000;1.15423;1
  29.70300; 6.16000; 4.491369e-003;100.13044;20.00000;1.15423;1
  29.70900; 6.20000; 4.651769e-003;100.13650;20.00000;1.15423;1
  29.72100; 6.24000; 4.531455e-003;100.13650;20.00000;1.15424;1
  29.75300; 6.28000; 4.270769e-003;100.13650;20.00000;1.15424;1
  29.75300; 6.32000; 4.330921e-003;100.13044;20.00000;1.15424;1
  29.79400; 6.36000; 4.170484e-003;100.13044;20.00000;1.15425;1
  29.77900; 6.40000; 4.090294e-003;100.13044;20.00000;1.15425;1
  29.79000; 6.44000; 4.010084e-003;100.13044;20.00000;1.15425;1
  29.80900; 6.48000; 3.929868e-003;100.13044;20.00000;1.15426;1
  29.82600; 6.52000; 3.949906e-003;100.12437;20.00000;1.15426;1
  29.84000; 6.56000; 3.789493e-003;100.12437;20.00000;1.15426;1
  29.84400; 6.60000; 3.729340e-003;100.12437;20.00000;1.15426;1
  29.85300; 6.64000; 3.709283e-003;100.12437;20.00000;1.15427;1
  29.88900; 6.68000; 3.388457e-003;100.12437;20.00000;1.15427;1
  29.89700; 6.72000; 3.709252e-003;100.12437;20.00000;1.15427;1
  29.90700; 6.76000; 3.388445e-003;100.12437;20.00000;1.15428;1
  29.91600; 6.80000; 3.228040e-003;100.12437;20.00000;1.15428;1
  29.92500; 6.84000; 3.167885e-003;100.12437;20.00000;1.15428;1
  29.93900; 6.88000; 3.167876e-003;100.11830;20.00000;1.15428;1
  29.96600; 6.92000; 3.027512e-003;100.11527;20.00000;1.15429;1
  29.97000; 6.96000; 3.007460e-003;100.11527;20.00000;1.15429;1
  29.96100; 7.00000; 2.786917e-003;100.11527;20.00000;1.15429;1
  29.97900; 7.04000; 2.987405e-003;100.11527;20.00000;1.15429;1
  29.98000; 7.08000; 3.007454e-003;100.11527;20.00000;1.15429;1
  29.99700; 7.12000; 2.726749e-003;100.11527;20.00000;1.15430;1
  30.00900; 7.16000; 2.646545e-003;100.11527;20.00000;1.15430;1
  30.02700; 7.20000; 2.726733e-003;100.11527;20.00000;1.15430;1
  30.04100; 7.24000; 2.666578e-003;100.11527;20.00000;1.15431;1
  30.03300; 7.28000; 2.566335e-003;100.11527;20.00000;1.15430;1
  30.04700; 7.32000; 2.546278e-003;100.11830;20.00000;1.15431;1
  30.05900; 7.36000; 2.486124e-003;100.11830;20.00000;1.15431;1
  30.07400; 7.40000; 2.245525e-003;100.11830;20.00000;1.15431;1
  30.06900; 7.44000; 2.245527e-003;100.11830;20.00000;1.15431;1
  30.09100; 7.48000; 2.345764e-003;100.11830;20.00000;1.15432;1
  30.08800; 7.52000; 2.225470e-003;100.11830;20.00000;1.15432;1
  30.11100; 7.56000; 2.165313e-003;100.11830;20.00000;1.15432;1
  30.12000; 7.60000; 2.245505e-003;100.11830;20.00000;1.15432;1
  30.12200; 7.64000; 2.185357e-003;100.11830;20.00000;1.15432;1
  30.13100; 7.68000; 2.305648e-003;100.11830;20.00000;1.15433;1
  30.14100; 7.72000; 2.105153e-003;100.11830;20.00000;1.15433;1
  30.14100; 7.76000; 1.964809e-003;100.11830;20.00000;1.15433;1
  30.15900; 7.80000; 1.824460e-003;100.11830;20.00000;1.15433;1
  30.17800; 7.84000; 1.724208e-003;100.11830;20.00000;1.15434;1
  30.17900; 7.88000; 1.623963e-003;100.11830;20.00000;1.15434;1
  30.19700; 7.92000; 1.784349e-003;100.11830;20.00000;1.15434;1
  30.20200; 7.96000; 1.844493e-003;100.12134;20.00000;1.15434;1
  30.19100; 8.00000; 1.583862e-003;100.12134;20.00000;1.15434;1
  30.20800; 8.04000; 1.644003e-003;100.12437;20.00000;1.15434;1
  30.20400; 8.08000; 1.563809e-003;100.12134;20.00000;1.15434;1
  30.22000; 8.12000; 1.523707e-003;100.12134;20.00000;1.15435;1
  30.22900; 8.16000; 1.583851e-003;100.12134;20.00000;1.15435;1
  30.23500; 8.20000; 1.583849e-003;100.12134;20.00000;1.15435;1
  30.24200; 8.24000; 1.443506e-003;100.12437;20.00000;1.15435;1
  30.23900; 8.28000; 1.323214e-003;100.12437;20.00000;1.15435;1
  30.24600; 8.32000; 1.403407e-003;100.12437;20.00000;1.15435;1
  30.26500; 8.36000; 1.243013e-003;100.12437;20.00000;1.15436;1
  30.26900; 8.40000; 1.423450e-003;100.12437;20.00000;1.15436;1
  30.28300; 8.44000; 1.463543e-003;100.12437;20.00000;1.15436;1
  30.29200; 8.48000; 1.222958e-003;100.12437;20.00000;1.15436;1
  30.27200; 8.52000; 1.062575e-003;100.12134;20.00000;1.15436;1
  30.29300; 8.56000; 1.222958e-003;100.12134;20.00000;1.15436;1
  30.29800; 8.60000; 1.082618e-003;100.12134;20.00000;1.15436;1
  30.30200; 8.64000; 9.222292e-004;100.12134;20.00000;1.15436;1
  30.32000; 8.68000; 1.062565e-003;100.12134;20.00000;1.15437;1
  30.30500; 8.72000; 1.002423e-003;100.12134;20.00000;1.15436;1
  30.32300; 8.76000; 1.022467e-003;100.12134;20.00000;1.15437;1
  30.33200; 8.80000; 9.623207e-004;100.12134;20.00000;1.15437;1
  30.33700; 8.84000; 9.222231e-004;100.12134;20.00000;1.15437;1
  30.33400; 8.88000; 8.420303e-004;100.12134;20.00000;1.15437;1
  30.34800; 8.92000; 9.021729e-004;100.12134;20.00000;1.15437;1
  30.34200; 8.96000; 8.420289e-004;100.12134;20.00000;1.15437;1
  30.36200; 9.00000; 9.021705e-004;100.12134;20.00000;1.15438;1
  30.37500; 9.04000; 7.818792e-004;100.12134;20.00000;1.15438;1
  30.37200; 9.08000; 7.016868e-004;100.12134;20.00000;1.15438;1
  30.37900; 9.12000; 8.420230e-004;100.12134;20.00000;1.15438;1
  30.37900; 9.16000; 7.618304e-004;100.12134;20.00000;1.15438;1
  30.38600; 9.20000; 8.620701e-004;100.12134;20.00000;1.15438;1
  30.38400; 9.24000; 9.021667e-004;100.12134;20.00000;1.15438;1
  30.40300; 9.28000; 7.417788e-004;100.12134;20.00000;1.15439;1
  30.39300; 9.32000; 7.417803e-004;100.12134;20.00000;1.15438;1
  30.39900; 9.36000; 8.620680e-004;100.12134;20.00000;1.15439;1
  30.39500; 9.40000; 8.420205e-004;100.12134;20.00000;1.15438;1
  30.41000; 9.44000; 8.620661e-004;100.12134;20.00000;1.15439;1
  30.41300; 9.48000; 5.813931e-004;100.12134;20.00000;1.15439;1
  30.42400; 9.52000; 5.212479e-004;100.12134;20.00000;1.15439;1
  30.43500; 9.56000; 6.214866e-004;100.12740;20.00000;1.15439;1
  30.42900; 9.60000; 6.615833e-004;100.12134;20.00000;1.15439;1
  30.44500; 9.64000; 7.417729e-004;100.12134;20.00000;1.15440;1
  30.43500; 9.68000; 6.214866e-004;100.12134;20.00000;1.15439;1
  30.46000; 9.72000; 6.615794e-004;100.12134;20.00000;1.15440;1
  30.44700; 9.76000; 6.415331e-004;100.12134;20.00000;1.15440;1
  30.44200; 9.80000; 6.214858e-004;100.12134;20.00000;1.15439;1
  30.46200; 9.84000; 7.016748e-004;100.12134;20.00000;1.15440;1
  30.46600; 9.88000; 6.615787e-004;100.12134;20.00000;1.15440;1
  30.47200; 9.92000; 6.615779e-004;100.12134;20.00000;1.15440;1
  30.46300; 9.96000; 6.214833e-004;100.12134;20.00000;1.15440;1
  30.47500;10.00000; 7.417687e-004;100.12134;20.00000;1.15440;1
  30.49300;10.04000; 5.412888e-004;100.12134;20.00000;1.15441;1
  30.48200;10.08000; 6.214810e-004;100.12134;20.00000;1.15440;1
  30.48800;10.12000; 5.412893e-004;100.12134;20.00000;1.15440;1
  30.49900;10.16000; 7.016699e-004;100.12134;20.00000;1.15441;1
  30.50700;10.20000; 6.816211e-004;100.12134;20.00000;1.15441;1
  30.49200;10.24000; 7.217186e-004;100.12134;20.00000;1.15441;1
  30.50900;10.28000; 7.016686e-004;100.12134;20.00000;1.15441;1
  30.51100;10.32000; 6.214777e-004;100.12134;20.00000;1.15441;1
  30.50500;10.36000; 4.610968e-004;100.12134;20.00000;1.15441;1
  30.53200;10.40000; 5.011896e-004;100.12134;20.00000;1.15441;1
  30.51700;10.44000; 3.408099e-004;100.12134;20.00000;1.15441;1
  30.52000;10.48000; 3.007145e-004;100.12134;20.00000;1.15441;1
  30.51800;10.52000; 4.210004e-004;100.12134;20.00000;1.15441;1
  30.53200;10.56000; 4.209993e-004;100.12134;20.00000;1.15441;1
  30.54500;10.60000; 4.410458e-004;100.12134;20.00000;1.15442;1
  30.53900;10.64000; 5.412841e-004;100.12134;20.00000;1.15442;1
  30.54500;10.68000; 3.608557e-004;100.12134;20.00000;1.15442;1
  30.55600;10.72000; 3.608549e-004;100.12437;20.00000;1.15442;1
  30.54500;10.76000; 3.007131e-004;100.12437;20.00000;1.15442;1
  30.56500;10.80000; 3.207594e-004;100.12437;20.00000;1.15442;1
  30.54300;10.84000; 2.806656e-004;100.12740;20.00000;1.15442;1
  30.58000;10.88000; 2.806636e-004;100.12740;20.00000;1.15442;1
  30.57200;10.92000; 3.608538e-004;100.12740;20.00000;1.15442;1
  30.57800;10.96000; 1.603793e-004;100.12740;20.00000;1.15442;1
  30.57100;11.00000; 1.804269e-004;100.13044;20.00000;1.15442;1
  30.56300;11.04000; 3.007120e-004;100.13044;20.00000;1.15442;1
  30.57800;11.08000; 2.004741e-004;100.13044;20.00000;1.15442;1
  30.58400;11.12000; 4.009478e-005;100.13044;20.00000;1.15443;1
  30.58400;11.16000; 6.014217e-005;100.13044;20.00000;1.15443;1
  30.58900;11.20000; 1.202842e-004;100.13044;20.00000;1.15443;1
  30.56600;11.24000; 2.004746e-005;100.12740;20.00000;1.15442;1
  30.59900;11.28000; 6.014200e-005;100.12740;20.00000;1.15443;1
  30.59000;11.32000;-6.014210e-005;100.12740;20.00000;1.15443;1
  30.59200;11.36000;-2.405683e-004;100.12740;20.00000;1.15443;1
  30.60200;11.40000;-4.009464e-005;100.12740;20.00000;1.15443;1
  30.59300;11.44000;-3.007103e-004;100.12437;20.00000;1.15443;1
  30.60500;11.48000;-3.007097e-004;100.12437;20.00000;1.15443;1
  30.60700;11.52000;-2.606149e-004;100.12134;20.00000;1.15443;1
  30.59600;11.56000;-2.806628e-004;100.12134;20.00000;1.15443;1
  30.61300;11.60000;-3.007092e-004;100.12134;20.00000;1.15443;1
  30.61000;11.64000;-2.205202e-004;100.11830;20.00000;1.15443;1
  30.61300;11.68000;-3.007092e-004;100.11830;20.00000;1.15443;1
  30.61100;11.72000;-3.408039e-004;100.11830;20.00000;1.15443;1
  30.62300;11.76000;-3.007086e-004;100.11830;20.00000;1.15443;1
  30.62000;11.80000;-3.808978e-004;100.11830;20.00000;1.15443;1
  30.62900;11.84000;-3.207555e-004;100.11527;20.00000;1.15444;1
  30.60600;11.88000;-4.009461e-004;100.11527;20.00000;1.15443;1
  30.62600;11.92000;-4.610863e-004;100.11527;20.00000;1.15443;1
  30.62800;11.96000;-6.615584e-004;100.11527;20.00000;1.15444;1
  30.64300;12.00000;-5.412735e-004;100.11527;20.00000;1.15444;1
  30.63300;12.04000;-5.813689e-004;100.11527;20.00000;1.15444;1
  30.63700;12.08000;-6.214628e-004;100.11527;20.00000;1.15444;1
  30.64900;12.12000;-5.613200e-004;100.12134;20.00000;1.15444;1
  30.63400;12.16000;-6.615576e-004;100.12134;20.00000;1.15444;1
  30.62300;12.20000;-5.412755e-004;100.12134;20.00000;1.15443;1
  30.64000;12.24000;-6.214625e-004;100.11830;20.00000;1.15444;1
  30.63500;12.28000;-6.415103e-004;100.11830;20.00000;1.15444;1
  30.63500;12.32000;-6.615575e-004;100.11830;20.00000;1.15444;1
  30.64200;12.36000;-7.016509e-004;100.11830;20.00000;1.15444;1
  30.63900;12.40000;-5.412738e-004;100.11830;20.00000;1.15444;1
  30.63600;12.44000;-5.813686e-004;100.11830;20.00000;1.15444;1
  30.65100;12.48000;-6.415083e-004;100.11830;20.00000;1.15444;1
  30.64500;12.52000;-6.214619e-004;100.11830;20.00000;1.15444;1
  30.66000;12.56000;-7.216956e-004;100.11830;20.00000;1.15444;1
  30.66400;12.60000;-7.417422e-004;100.11830;20.00000;1.15444;1
  30.67700;12.64000;-7.818345e-004;100.11224;20.00000;1.15445;1
  30.66200;12.68000;-8.419779e-004;100.11224;20.00000;1.15444;1
  30.67400;12.72000;-7.216937e-004;100.11224;20.00000;1.15445;1
  30.66600;12.76000;-8.219302e-004;100.11224;20.00000;1.15444;1
  30.69000;12.80000;-6.815976e-004;100.11224;20.00000;1.15445;1
  30.66300;12.84000;-7.617894e-004;100.11224;20.00000;1.15444;1
  30.67700;12.88000;-7.216933e-004;100.11224;20.00000;1.15445;1
  30.69100;12.92000;-7.216914e-004;100.11224;20.00000;1.15445;1
  30.69900;12.96000;-7.617843e-004;100.11830;20.00000;1.15445;1
  30.68900;13.00000;-5.613158e-004;100.11830;20.00000;1.15445;1
  30.68000;13.04000;-8.419751e-004;100.11830;20.00000;1.15445;1
  30.68200;13.08000;-8.419748e-004;100.11830;20.00000;1.15445;1
  30.68000;13.12000;-8.419751e-004;100.11830;20.00000;1.15445;1
  30.68500;13.16000;-8.219272e-004;100.11830;20.00000;1.15445;1
  30.67800;13.20000;-7.417402e-004;100.11830;20.00000;1.15445;1
  30.69900;13.24000;-7.818312e-004;100.11830;20.00000;1.15445;1
  30.70600;13.28000;-7.617832e-004;100.11830;20.00000;1.15445;1
  30.70100;13.32000;-8.419717e-004;100.12437;20.00000;1.15445;1
  30.69600;13.36000;-8.419725e-004;100.12437;20.00000;1.15445;1
  30.69300;13.40000;-7.818321e-004;100.12437;20.00000;1.15445;1
  30.71400;13.44000;-8.419697e-004;100.12437;20.00000;1.15445;1
  30.71300;13.48000;-8.219229e-004;100.12134;20.00000;1.15445;1
  30.70800;13.52000;-7.216891e-004;100.11527;20.00000;1.15445;1
  30.71200;13.56000;-8.018762e-004;100.10920;20.00000;1.15445;1
  30.71200;13.60000;-7.216886e-004;100.10920;20.00000;1.15445;1
  30.71700;13.64000;-9.622505e-004;100.10920;20.00000;1.15445;1
  30.70300;13.68000;-6.415020e-004;100.10920;20.00000;1.15445;1
  30.72600;13.72000;-9.021083e-004;100.10920;20.00000;1.15446;1
  30.71200;13.76000;-9.221576e-004;100.11224;20.00000;1.15445;1
  30.71800;13.80000;-8.018753e-004;100.11224;20.00000;1.15445;1
  30.71500;13.84000;-8.820633e-004;100.11224;20.00000;1.15445;1
  30.70600;13.88000;-8.820648e-004;100.11224;20.00000;1.15445;1
  30.73400;13.92000;-6.815920e-004;100.11224;20.00000;1.15446;1
  30.73000;13.96000;-7.617798e-004;100.11224;20.00000;1.15446;1
  30.72500;14.00000;-7.016399e-004;100.11224;20.00000;1.15446;1
  30.73100;14.04000;-5.613113e-004;100.11224;20.00000;1.15446;1
  30.73700;14.08000;-8.018724e-004;100.11224;20.00000;1.15446;1
  30.73700;14.12000;-8.419660e-004;100.11527;20.00000;1.15446;1
  30.73000;14.16000;-8.620140e-004;100.11527;20.00000;1.15446;1
  30.74000;14.20000;-6.615444e-004;100.12134;20.00000;1.15446;1
  30.72100;14.24000;-8.018748e-004;100.12437;20.00000;1.15446;1
  30.71500;14.28000;-7.216881e-004;100.12437;20.00000;1.15445;1
  30.75000;14.32000;-7.216834e-004;100.12740;20.00000;1.15446;1
  30.73600;14.36000;-7.016385e-004;100.12740;20.00000;1.15446;1
  30.74300;14.40000;-8.219182e-004;100.12740;20.00000;1.15446;1
  30.73000;14.44000;-6.815924e-004;100.12740;20.00000;1.15446;1
  30.73600;14.48000;-8.219194e-004;100.12740;20.00000;1.15446;1
  30.73600;14.52000;-7.617789e-004;100.12740;20.00000;1.15446;1
  30.73500;14.56000;-7.216855e-004;100.12740;20.00000;1.15446;1
  30.73500;14.60000;-9.021068e-004;100.12437;20.00000;1.15446;1
  30.74800;14.64000;-9.021046e-004;100.12437;20.00000;1.15446;1
  30.73000;14.68000;-9.622481e-004;100.12740;20.00000;1.15446;1
  30.75100;14.72000;-9.021040e-004;100.12740;20.00000;1.15446;1
  30.73900;14.76000;-8.620125e-004;100.12437;20.00000;1.15446;1
  30.73100;14.80000;-7.016391e-004;100.12437;20.00000;1.15446;1
  30.72500;14.84000;-8.620148e-004;100.12134;20.00000;1.15446;1
  30.75300;14.88000;-8.419635e-004;100.12134;20.00000;1.15446;1
  30.75100;14.92000;-9.221508e-004;100.12134;20.00000;1.15446;1
  30.75600;14.96000;-8.419629e-004;100.12134;20.00000;1.15446;1
  30.74800;15.00000;-9.021046e-004;100.12134;20.00000;1.15446;1
  30.75200;15.04000;-8.419636e-004;100.12134;20.00000;1.15446;1
  30.75400;15.08000;-9.622438e-004;100.12134;20.00000;1.15446;1
  30.76500;15.12000;-1.122615e-003;100.12134;20.00000;1.15447;1
  30.74300;15.16000;-9.021054e-004;100.11830;20.00000;1.15446;1
  30.76000;15.20000;-1.062476e-003;100.11830;20.00000;1.15446;1
  30.75600;15.24000;-1.142664e-003;100.11830;20.00000;1.15446;1
  30.77200;15.28000;-1.202801e-003;100.11830;20.00000;1.15447;1
  30.75200;15.32000;-9.221507e-004;100.11830;20.00000;1.15446;1
  30.76000;15.36000;-1.062476e-003;100.11830;20.00000;1.15446;1
  30.77400;15.40000;-8.419601e-004;100.12134;20.00000;1.15447;1
  30.77600;15.44000;-1.082520e-003;100.12134;20.00000;1.15447;1
  30.76300;15.48000;-9.421954e-004;100.12134;20.00000;1.15446;1
  30.74700;15.52000;-1.002339e-003;100.12134;20.00000;1.15446;1
  30.77500;15.56000;-1.002333e-003;100.12134;20.00000;1.15447;1
  30.76800;15.60000;-1.022381e-003;100.12134;20.00000;1.15447;1
  30.77000;15.64000;-1.022381e-003;100.12134;20.00000;1.15447;1
  30.77100;15.68000;-9.021007e-004;100.12134;20.00000;1.15447;1
  30.76200;15.72000;-9.822890e-004;100.12134;20.00000;1.15446;1
  30.76800;15.76000;-1.062475e-003;100.12134;20.00000;1.15447;1
  30.76500;15.80000;-9.622418e-004;100.11830;20.00000;1.15447;1
  30.76900;15.84000;-1.102568e-003;100.11830;20.00000;1.15447;1
  30.76300;15.88000;-1.142663e-003;100.11830;20.00000;1.15446;1
  30.76800;15.92000;-1.102568e-003;100.11830;20.00000;1.15447;1
  30.77600;15.96000;-1.082520e-003;100.11830;20.00000;1.15447;1
  30.77200;16.00000;-9.421938e-004;100.11830;20.00000;1.15447;1
  30.77700;16.04000;-1.242893e-003;100.11224;20.00000;1.15447;1
  30.77700;16.08000;-1.182753e-003;100.11224;20.00000;1.15447;1
  30.78600;16.12000;-1.182751e-003;100.11224;20.00000;1.15447;1
  30.77200;16.16000;-1.102567e-003;100.11224;20.00000;1.15447;1
  30.76300;16.20000;-1.122616e-003;100.11224;20.00000;1.15446;1
  30.77500;16.24000;-1.002333e-003;100.11224;20.00000;1.15447;1
  30.79000;16.28000;-1.122610e-003;100.11224;20.00000;1.15447;1
  30.78700;16.32000;-1.022378e-003;100.11224;20.00000;1.15447;1
  30.78500;16.36000;-1.122611e-003;100.11224;20.00000;1.15447;1
  30.76900;16.40000;-1.062475e-003;100.11224;20.00000;1.15447;1
  30.79100;16.44000;-1.022377e-003;100.11224;20.00000;1.15447;1
  30.77600;16.48000;-8.820531e-004;100.11224;20.00000;1.15447;1
  30.78100;16.52000;-9.020990e-004;100.11224;20.00000;1.15447;1
  30.76400;16.56000;-8.419617e-004;100.11224;20.00000;1.15446;1
  30.77700;16.60000;-1.002333e-003;100.11224;20.00000;1.15447;1
  30.76900;16.64000;-9.221477e-004;100.11224;20.00000;1.15447;1
  30.79200;16.68000;-8.820504e-004;100.11224;20.00000;1.15447;1
  30.77400;16.72000;-9.221468e-004;100.11224;20.00000;1.15447;1
  30.75600;16.76000;-8.419629e-004;100.11224;20.00000;1.15446;1
  30.79000;16.80000;-7.016313e-004;100.11224;20.00000;1.15447;1
  30.76500;16.84000;-1.022382e-003;100.11224;20.00000;1.15447;1
  30.77800;16.88000;-9.421927e-004;100.11224;20.00000;1.15447;1
  30.77000;16.92000;-9.021009e-004;100.11224;20.00000;1.15447;1
  30.78600;16.96000;-8.820514e-004;100.11224;20.00000;1.15447;1
  30.77200;17.00000;-8.820538e-004;100.11224;20.00000;1.15447;1
  30.77300;17.04000;-9.421936e-004;100.11224;20.00000;1.15447;1
  30.77200;17.08000;-8.018671e-004;100.11224;20.00000;1.15447;1
  30.78100;17.12000;-7.818191e-004;100.11224;20.00000;1.15447;1
  30.78500;17.16000;-8.820516e-004;100.11224;20.00000;1.15447;1
  30.80300;17.20000;-8.018624e-004;100.11224;20.00000;1.15447;1
  30.80200;17.24000;-9.421885e-004;100.11224;20.00000;1.15447;1
  30.79700;17.28000;-8.219099e-004;100.11224;20.00000;1.15447;1
  30.78700;17.32000;-9.020979e-004;100.11224;20.00000;1.15447;1
  30.79400;17.36000;-7.417240e-004;100.11224;20.00000;1.15447;1
  30.78300;17.40000;-6.815856e-004;100.11224;20.00000;1.15447;1
  30.78200;17.44000;-7.216790e-004;100.11224;20.00000;1.15447;1
  30.78900;17.48000;-6.615382e-004;100.11224;20.00000;1.15447;1
  30.80200;17.52000;-7.016297e-004;100.11224;20.00000;1.15447;1
  30.80200;17.56000;-6.414900e-004;100.11224;20.00000;1.15447;1
  30.79100;17.60000;-6.414913e-004;100.11830;20.00000;1.15447;1
  30.79100;17.64000;-7.016312e-004;100.11830;20.00000;1.15447;1
  30.78800;17.68000;-6.615384e-004;100.11830;20.00000;1.15447;1
  30.80600;17.72000;-9.221413e-004;100.11830;20.00000;1.15447;1
  30.79900;17.76000;-6.615370e-004;100.11830;20.00000;1.15447;1
  30.79100;17.80000;-6.815845e-004;100.11830;20.00000;1.15447;1
  30.80300;17.84000;-9.020951e-004;100.11830;20.00000;1.15447;1
  30.78600;17.88000;-9.221447e-004;100.11830;20.00000;1.15447;1
  30.77300;17.92000;-8.820536e-004;100.11830;20.00000;1.15447;1
  30.80800;17.96000;-8.620013e-004;100.11830;20.00000;1.15447;1
  30.78800;18.00000;-9.020978e-004;100.11830;20.00000;1.15447;1
  30.78800;18.04000;-1.002331e-003;100.11830;20.00000;1.15447;1
  30.81100;18.08000;-8.620008e-004;100.11830;20.00000;1.15448;1
  30.81500;18.12000;-1.022372e-003;100.11830;20.00000;1.15448;1
  30.79100;18.16000;-1.242889e-003;100.11830;20.00000;1.15447;1
  30.81000;18.20000;-1.202792e-003;100.11830;20.00000;1.15447;1
  30.81200;18.24000;-1.122605e-003;100.11224;20.00000;1.15448;1
  30.79200;18.28000;-1.142656e-003;100.11224;20.00000;1.15447;1
  30.79400;18.32000;-1.102563e-003;100.11224;20.00000;1.15447;1
  30.78600;18.36000;-1.202797e-003;100.11224;20.00000;1.15447;1
  30.79400;18.40000;-1.222842e-003;100.11224;20.00000;1.15447;1
  30.80700;18.44000;-1.222839e-003;100.11224;20.00000;1.15447;1
  30.80700;18.48000;-1.222839e-003;100.11224;20.00000;1.15447;1
  30.80100;18.52000;-1.062468e-003;100.11224;20.00000;1.15447;1
  30.79300;18.56000;-1.242889e-003;100.11224;20.00000;1.15447;1
  30.79100;18.60000;-1.443356e-003;100.11224;20.00000;1.15447;1
  30.80300;18.64000;-1.443352e-003;100.11830;20.00000;1.15447;1
  30.80100;18.68000;-1.282980e-003;100.11224;20.00000;1.15447;1
  30.80400;18.72000;-1.343119e-003;100.11224;20.00000;1.15447;1
  30.79200;18.76000;-1.363169e-003;100.11224;20.00000;1.15447;1
  30.80500;18.80000;-1.202793e-003;100.11224;20.00000;1.15447;1
  30.79300;18.84000;-1.122610e-003;100.11224;20.00000;1.15447;1
  30.80600;18.88000;-1.222839e-003;100.11224;20.00000;1.15447;1
  30.79100;18.92000;-1.303029e-003;100.11224;20.00000;1.15447;1
  30.79700;18.96000;-1.323074e-003;100.11224;20.00000;1.15447;1
  30.78300;19.00000;-1.282985e-003;100.11224;20.00000;1.15447;1
  30.81400;19.04000;-1.343117e-003;100.11224;20.00000;1.15448;1
  30.80700;19.08000;-1.323072e-003;100.11224;20.00000;1.15447;1
  30.79500;19.12000;-1.323075e-003;100.10617;20.00000;1.15447;1
  30.80900;19.16000;-1.182746e-003;100.10617;20.00000;1.15447;1
  30.82200;19.20000;-1.242882e-003;100.10617;20.00000;1.15448;1
  30.80500;19.24000;-1.282979e-003;100.10617;20.00000;1.15447;1
  30.80600;19.28000;-1.262933e-003;100.10617;20.00000;1.15447;1
  30.79500;19.32000;-1.222842e-003;100.10617;20.00000;1.15447;1
  30.80600;19.36000;-1.222839e-003;100.10617;20.00000;1.15447;1
  30.80300;19.40000;-1.262933e-003;100.10617;20.00000;1.15447;1
  30.81000;19.44000;-1.122606e-003;100.10617;20.00000;1.15447;1
  30.79100;19.48000;-1.082517e-003;100.10617;20.00000;1.15447;1
  30.79500;19.52000;-1.162702e-003;100.10617;20.00000;1.15447;1
  30.78900;19.56000;-1.122610e-003;100.10617;20.00000;1.15447;1
  30.80100;19.60000;-1.162701e-003;100.10617;20.00000;1.15447;1
  30.82000;19.64000;-1.122604e-003;100.10010;20.00000;1.15448;1
  30.81200;19.68000;-1.122605e-003;100.10010;20.00000;1.15448;1
  30.80800;19.72000;-1.062467e-003;100.10010;20.00000;1.15447;1
  30.82000;19.76000;-1.182743e-003;100.10010;20.00000;1.15448;1
  30.80600;19.80000;-1.162700e-003;100.10010;20.00000;1.15447;1
  30.81800;19.84000;-1.082511e-003;100.10010;20.00000;1.15448;1
  30.82100;19.88000;-1.142650e-003;100.10010;20.00000;1.15448;1
  30.81500;19.92000;-9.622326e-004;100.09707;20.00000;1.15448;1
  30.81900;19.96000;-1.002325e-003;100.10010;20.00000;1.15448;1
  30.80700;19.99750;-1.102560e-003;100.10010;20.00000;1.15447;1
  30.80100;20.03750;-1.062468e-003;100.10010;20.00000;1.15447;2
  30.81500;20.07750;-1.062465e-003;100.10010;20.00000;1.15448;2
  30.80200;20.11750;-1.062468e-003;100.10010;20.00000;1.15447;2
  30.79800;20.15750;-1.082515e-003;100.10010;20.00000;1.15447;2
  30.81100;20.19750;-9.822800e-004;100.10010;20.00000;1.15448;2
  30.79800;20.23750;-1.022376e-003;100.10010;20.00000;1.15447;2
  30.81500;20.27750;-8.018605e-004;100.10010;20.00000;1.15448;2
  30.82500;20.31750;-7.617661e-004;100.10010;20.00000;1.15448;2
  30.82000;20.35750;-4.410229e-004;100.10617;20.00000;1.15448;2
  30.82300;20.39750;-1.202789e-004;100.11224;20.00000;1.15448;2
  30.83200;20.43750; 2.205109e-004;100.11224;20.00000;1.15448;2
  30.84300;20.47750; 8.219027e-004;100.10920;20.00000;1.15448;2
  30.86000;20.51750; 1.282966e-003;100.11224;20.00000;1.15449;2
  30.87700;20.55750; 2.365461e-003;100.11527;20.00000;1.15449;2
  30.91400;20.59750; 2.886651e-003;100.11527;20.00000;1.15450;2
  30.92400;20.63750; 4.329964e-003;100.11830;20.00000;1.15450;2
  30.95900;20.67750; 5.412418e-003;100.11527;20.00000;1.15451;2
  31.00000;20.71750; 6.815583e-003;100.11527;20.00000;1.15452;2
  31.03800;20.75750; 8.419189e-003;100.11830;20.00000;1.15452;2
  31.08600;20.79750; 1.042366e-002;100.12134;20.00000;1.15454;2
  31.14200;20.83750; 1.244813e-002;100.12437;20.00000;1.15455;2
  31.22000;20.87750; 1.455267e-002;100.12437;20.00000;1.15456;2
  31.28900;20.91750; 1.739884e-002;100.12740;20.00000;1.15458;2
  31.37000;20.95750; 2.024488e-002;100.12740;20.00000;1.15460;2
  31.48400;20.99750; 2.303057e-002;100.12437;20.00000;1.15462;2
  31.56100;21.03750; 2.627731e-002;100.12134;20.00000;1.15464;2
  31.66800;21.07750; 2.934342e-002;100.12134;20.00000;1.15466;2
  31.77700;21.11750; 3.287037e-002;100.11830;20.00000;1.15468;2
  31.92600;21.15750; 3.693806e-002;100.11830;20.00000;1.15472;2
  32.05400;21.19750; 4.072510e-002;100.12134;20.00000;1.15474;2
  32.21100;21.23750; 4.507288e-002;100.11830;20.00000;1.15478;2
  32.34100;21.27750; 4.946073e-002;100.12134;20.00000;1.15480;2
  32.52100;21.31750; 5.406833e-002;100.11830;20.00000;1.15484;2
  32.70200;21.35750; 5.875577e-002;100.11830;20.00000;1.15488;2
  32.89400;21.39750; 6.366320e-002;100.11830;20.00000;1.15492;2
  33.09500;21.43750; 6.875052e-002;100.11830;20.00000;1.15496;2
  33.31200;21.47750; 7.391744e-002;100.11830;20.00000;1.15501;2
  33.53700;21.51750; 7.934429e-002;100.11830;20.00000;1.15506;2
  33.76500;21.55750; 8.475064e-002;100.11830;20.00000;1.15510;2
  34.01600;21.59750; 9.065704e-002;100.11830;20.00000;1.15516;2
  34.27000;21.63750; 9.614217e-002;100.11830;20.00000;1.15521;2
  34.52500;21.67750;       0.10189;100.11830;20.00000;1.15526;2
  34.81600;21.71750;       0.10791;100.11527;20.00000;1.15532;2
  35.10900;21.75750;       0.11406;100.11527;20.00000;1.15538;2
  35.40400;21.79750;       0.12024;100.11527;20.00000;1.15544;2
  35.72100;21.83750;       0.12652;100.11830;20.00000;1.15551;2
  36.05800;21.87750;       0.13270;100.11527;20.00000;1.15557;2
  36.39000;21.91750;       0.13912;100.11527;20.00000;1.15564;2
  36.73900;21.95750;       0.14522;100.11527;20.00000;1.15571;2
  37.08100;21.99750;       0.15196;100.11830;20.00000;1.15578;2
  37.44900;22.03750;       0.15830;100.11527;20.00000;1.15585;2
  37.82700;22.07750;       0.16474;100.11830;20.00000;1.15593;2
  38.20800;22.11750;       0.17117;100.11527;20.00000;1.15600;2
  38.59300;22.15750;       0.17775;100.11830;20.00000;1.15607;2
  39.00300;22.19750;       0.18428;100.11527;20.00000;1.15615;2
  39.42100;22.23750;       0.19065;100.11224;20.00000;1.15623;2
  39.84700;22.27750;       0.19698;100.11527;20.00000;1.15631;2
  40.26500;22.31750;       0.20372;100.10920;20.00000;1.15639;2
  40.71400;22.35750;       0.21034;100.11224;20.00000;1.15648;2
  41.17600;22.39750;       0.21669;100.11527;20.00000;1.15656;2
  41.63200;22.43750;       0.22294;100.10920;20.00000;1.15665;2
  42.09200;22.47750;       0.22951;100.10617;20.00000;1.15673;2
  42.57800;22.51750;       0.23599;100.11224;20.00000;1.15682;2
  43.05900;22.55750;       0.24251;100.10617;20.00000;1.15691;2
  43.54700;22.59750;       0.24872;100.10617;20.00000;1.15699;2
  44.04900;22.63750;       0.25526;100.10617;20.00000;1.15708;2
  44.55000;22.67750;       0.26162;100.10617;20.00000;1.15717;2
  45.06000;22.71750;       0.26788;100.11224;20.00000;1.15726;2
  45.58100;22.75750;       0.27430;100.11527;20.00000;1.15735;2
  46.12900;22.79750;       0.28063;100.11527;20.00000;1.15744;2
  46.64100;22.83750;       0.28703;100.11830;20.00000;1.15753;2
  47.19300;22.87750;       0.29370;100.11527;20.00000;1.15762;2
  47.74600;22.91750;       0.30016;100.11830;20.00000;1.15771;2
  48.31300;22.95750;       0.30657;100.11830;20.00000;1.15780;2
  48.87300;22.99750;       0.31334;100.11830;20.00000;1.15789;2
  49.43900;23.03750;       0.32027;100.11830;20.00000;1.15798;2
  50.02100;23.07750;       0.32696;100.11830;20.00000;1.15807;2
  50.59800;23.11750;       0.33385;100.11224;20.00000;1.15816;2
  51.17800;23.15750;       0.34110;100.10920;20.00000;1.15825;2
  51.77300;23.19750;       0.34824;100.10920;20.00000;1.15834;2
  52.36700;23.23750;       0.35555;100.10617;20.00000;1.15843;2
  52.96800;23.27750;       0.36309;100.10920;20.00000;1.15852;2
  53.58900;23.31750;       0.37054;100.11527;20.00000;1.15861;2
  54.19200;23.35750;       0.37844;100.11224;20.00000;1.15870;2
  54.81200;23.39750;       0.38602;100.11527;20.00000;1.15879;2
  55.42500;23.43750;       0.39400;100.11527;20.00000;1.15887;2
  56.03800;23.47750;       0.40186;100.12134;20.00000;1.15896;2
  56.65800;23.51750;       0.40949;100.11830;20.00000;1.15904;2
  57.31700;23.55750;       0.41749;100.11830;20.00000;1.15913;2
  57.94900;23.59750;       0.42548;100.11830;20.00000;1.15922;2
  58.59300;23.63750;       0.43344;100.12134;20.00000;1.15930;2
  59.23000;23.67750;       0.44167;100.11830;20.00000;1.15938;2
  59.90300;23.71750;       0.44976;100.12437;20.00000;1.15947;2
  60.55800;23.75750;       0.45774;100.12134;20.00000;1.15955;2
  61.20500;23.79750;       0.46587;100.12437;20.00000;1.15963;2
  61.87000;23.83750;       0.47378;100.12437;20.00000;1.15971;2
  62.53900;23.87750;       0.48199;100.12437;20.00000;1.15979;2
  63.21100;23.91750;       0.49022;100.12437;20.00000;1.15986;2
  63.90200;23.95750;       0.49796;100.12437;20.00000;1.15994;2
  64.57100;23.99750;       0.50575;100.12437;20.00000;1.16002;2
  65.25700;24.03750;       0.51332;100.12740;20.00000;1.16009;2
  65.94400;24.07750;       0.52089;100.12437;20.00000;1.16016;2
  66.63300;24.11750;       0.52806;100.12437;20.00000;1.16024;2
  67.32200;24.15750;       0.53479;100.12740;20.00000;1.16031;2
  68.02300;24.19750;       0.54146;100.12740;20.00000;1.16038;2
  68.72400;24.23750;       0.54767;100.13347;20.00000;1.16045;2
  69.40900;24.27750;       0.55366;100.13044;20.00000;1.16051;2
  70.11200;24.31750;       0.55923;100.13347;20.00000;1.16058;2
  70.82200;24.35750;       0.56412;100.13044;20.00000;1.16064;2
  71.54200;24.39750;       0.56872;100.13347;20.00000;1.16071;2
  72.24500;24.43750;       0.57281;100.13347;20.00000;1.16077;2
  72.95800;24.47750;       0.57633;100.13347;20.00000;1.16083;2
  73.69500;24.51750;       0.57894;100.13347;20.00000;1.16089;2
  74.40700;24.55750;       0.58152;100.12740;20.00000;1.16095;2
  75.11300;24.59750;       0.58338;100.12740;20.00000;1.16100;2
  75.84100;24.63750;       0.58471;100.12740;20.00000;1.16105;2
  76.56300;24.67750;       0.58572;100.12740;20.00000;1.16111;2
  77.29100;24.71750;       0.58643;100.12437;20.00000;1.16116;2
  78.04100;24.75750;       0.58703;100.12437;20.00000;1.16121;2
  78.76600;24.79750;       0.58710;100.12437;20.00000;1.16126;2
  79.50000;24.83750;       0.58676;100.12437;20.00000;1.16130;2
  80.24400;24.87750;       0.58708;100.12134;20.00000;1.16135;2
  80.98400;24.91750;       0.58681;100.12437;20.00000;1.16139;2
  81.74300;24.95750;       0.58665;100.12437;20.00000;1.16144;2
  82.49500;24.99750;       0.58617;100.11830;20.00000;1.16148;2
  83.24800;25.03750;       0.58614;100.11830;20.00000;1.16151;2
  83.99100;25.07750;       0.58566;100.11527;20.00000;1.16155;2
  84.73700;25.11750;       0.58558;100.11830;20.00000;1.16159;2
  85.49400;25.15750;       0.58578;100.11830;20.00000;1.16162;2
  86.26700;25.19750;       0.58581;100.11527;20.00000;1.16165;2
  87.02500;25.23750;       0.58589;100.11527;20.00000;1.16168;2
  87.78900;25.27750;       0.58636;100.11224;20.00000;1.16171;2
  88.54600;25.31750;       0.58678;100.11527;20.00000;1.16174;2
  89.31900;25.35750;       0.58760;100.11224;20.00000;1.16176;2
  90.09800;25.39750;       0.58833;100.11527;20.00000;1.16178;2
  90.87300;25.43750;       0.58922;100.10920;20.00000;1.16180;2
  91.64800;25.47750;       0.59024;100.11224;20.00000;1.16182;2
  92.42900;25.51750;       0.59153;100.10617;20.00000;1.16184;2
  93.22000;25.55750;       0.59284;100.10617;20.00000;1.16185;2
  94.00000;25.59750;       0.59430;100.10314;20.00000;1.16187;2
  94.78500;25.63750;       0.59583;100.10010;20.00000;1.16188;2
  95.56900;25.67750;       0.59722;100.09707;20.00000;1.16189;2
  96.37100;25.71750;       0.59875;100.09404;20.00000;1.16190;2
  97.15500;25.75750;       0.60074;100.09404;20.00000;1.16190;2
  97.95100;25.79750;       0.60265;100.09404;20.00000;1.16190;2
  98.75800;25.83750;       0.60446;100.08797;20.00000;1.16191;2
  99.53900;25.87750;       0.60673;100.09404;20.00000;1.16190;2
 100.35000;25.91750;       0.60903;100.08797;20.00000;1.16190;2
 101.15500;25.95750;       0.61146;100.08797;20.00000;1.16190;2
 101.95100;25.99750;       0.61381;100.08797;20.00000;1.16189;2
 102.77300;26.03750;       0.61623;100.08190;20.00000;1.16188;2
 103.57200;26.07750;       0.61836;100.08190;20.00000;1.16187;2
 104.37100;26.11750;       0.62090;100.07584;20.00000;1.16186;2
 105.18300;26.15750;       0.62376;100.08190;20.00000;1.16184;2
 105.99000;26.19750;       0.62610;100.08190;20.00000;1.16182;2
 106.81000;26.23750;       0.62862;100.07584;20.00000;1.16180;2
 107.60800;26.27750;       0.63122;100.07584;20.00000;1.16178;2
 108.43200;26.31750;       0.63396;100.07584;20.00000;1.16176;2
 109.23300;26.35750;       0.63665;100.07584;20.00000;1.16173;2
 110.06300;26.39750;       0.63927;100.06977;20.00000;1.16170;2
 110.86500;26.43750;       0.64192;100.06674;20.00000;1.16167;2
 111.68400;26.47750;       0.64480;100.06370;20.00000;1.16164;2
 112.50100;26.51750;       0.64733;100.06370;20.00000;1.16160;2
 113.32300;26.55750;       0.65020;100.06067;20.00000;1.16157;2
 114.13100;26.59750;       0.65319;100.06067;20.00000;1.16153;2
 114.96200;26.63750;       0.65593;100.05764;20.00000;1.16149;2
 115.77200;26.67750;       0.65914;100.05460;20.00000;1.16144;2
 116.59000;26.71750;       0.66208;100.05157;20.00000;1.16140;2
 117.41000;26.75750;       0.66509;100.04853;20.00000;1.16135;2
 118.24600;26.79750;       0.66821;100.04247;20.00000;1.16130;2
 119.07000;26.83750;       0.67111;100.03640;20.00000;1.16125;2
 119.88800;26.87750;       0.67435;100.03033;20.00000;1.16119;2
 120.70700;26.91750;       0.67727;100.03033;20.00000;1.16113;2
 121.53300;26.95750;       0.68004;100.02427;20.00000;1.16108;2
 122.35700;26.99750;       0.68315;100.02427;20.00000;1.16101;2
 123.18300;27.03750;       0.68611;100.02427;20.00000;1.16095;2
 124.01000;27.07750;       0.68922;100.01820;20.00000;1.16088;2
 124.84300;27.11750;       0.69197;100.00607;20.00000;1.16082;2
 125.67700;27.15750;       0.69487;100.00303;20.00000;1.16074;2
 126.50900;27.19750;       0.69764; 99.99697;20.00000;1.16067;2
 127.34400;27.23750;       0.70040; 99.99393;20.00000;1.16060;2
 128.17599;27.27750;       0.70336; 99.99090;20.00000;1.16052;2
 129.01401;27.31750;       0.70610; 99.98483;20.00000;1.16044;2
 129.84900;27.35750;       0.70862; 99.97877;20.00000;1.16036;2
 130.69501;27.39750;       0.71129; 99.97270;20.00000;1.16027;2
 131.53000;27.43750;       0.71410; 99.96057;20.00000;1.16018;2
 132.37300;27.47750;       0.71678; 99.95753;20.00000;1.16009;2
 133.19800;27.51750;       0.71921; 99.94843;20.00000;1.16000;2
 134.04500;27.55750;       0.72181; 99.94236;20.00000;1.15991;2
 134.89900;27.59750;       0.72442; 99.93326;20.00000;1.15981;2
 135.74300;27.63750;       0.72702; 99.92720;20.00000;1.15971;2
 136.59300;27.67750;       0.72928; 99.91810;20.00000;1.15961;2
 137.41600;27.71750;       0.73158; 99.91203;20.00000;1.15951;2
 138.26900;27.75750;       0.73432; 99.90293;20.00000;1.15940;2
 139.11501;27.79750;       0.73650; 99.89080;20.00000;1.15929;2
 139.98100;27.83750;       0.73859; 99.88473;20.00000;1.15918;2
 140.82100;27.87750;       0.74092; 99.87260;20.00000;1.15907;2
 141.67999;27.91750;       0.74297; 99.86350;20.00000;1.15895;2
 142.52901;27.95750;       0.74510; 99.85136;20.00000;1.15883;2
 143.38200;27.99750;       0.74736; 99.83923;20.00000;1.15871;2
 144.25999;28.03750;       0.74950; 99.82709;20.00000;1.15858;2
 145.10201;28.07750;       0.75156; 99.81193;20.00000;1.15846;2
 145.96201;28.11750;       0.75370; 99.79069;20.00000;1.15833;2
 146.81900;28.15750;       0.75558; 99.77553;20.00000;1.15820;2
 147.68800;28.19750;       0.75777; 99.76036;20.00000;1.15806;2
 148.55299;28.23750;       0.75964; 99.74519;20.00000;1.15793;2
 149.41299;28.27750;       0.76145; 99.72699;20.00000;1.15779;2
 150.28000;28.31750;       0.76336; 99.70576;20.00000;1.15765;2
 151.14999;28.35750;       0.76515; 99.68756;20.00000;1.15750;2
 152.00800;28.39750;       0.76693; 99.66329;20.00000;1.15736;2
 152.87900;28.43750;       0.76859; 99.64206;20.00000;1.15721;2
 153.75301;28.47750;       0.77009; 99.61475;20.00000;1.15705;2
 154.62300;28.51750;       0.77227; 99.59352;20.00000;1.15690;2
 155.48700;28.55750;       0.77380; 99.56925;20.00000;1.15674;2
 156.35201;28.59750;       0.77497; 99.54499;20.00000;1.15659;2
 157.22600;28.63750;       0.77654; 99.52072;20.00000;1.15642;2
 158.09300;28.67750;       0.77797; 99.49948;20.00000;1.15626;2
 158.97501;28.71750;       0.77954; 99.46915;20.00000;1.15609;2
 159.83701;28.75750;       0.78094; 99.44488;20.00000;1.15592;2
 160.70200;28.79750;       0.78209; 99.41151;20.00000;1.15575;2
 161.57600;28.83750;       0.78371; 99.38421;20.00000;1.15558;2
 162.45200;28.87750;       0.78493; 99.35691;20.00000;1.15540;2
 162.67500;28.88750;       0.78531; 99.35388;20.00000;1.15535;2